Workbook
Name FromArray_1: _xlfn.ANCHORARRAY([2]БДДС!$IOT$1)
Name FromArray_1: _xlfn.ANCHORARRAY([2]БДДС!$IOT$1)
Name FromArray_1: _xlfn.ANCHORARRAY(#REF!)
Name FromArray_1: _xlfn.ANCHORARRAY(#REF!)
Name FromArray_1: _xlfn.ANCHORARRAY([2]БДДС!$IOT$1)
Name path: #REF!
Name path: #REF!
Name Дата_платежа: DATE(YEAR(Начало_кредита),MONTH(Начало_кредита)+'Анализ чувствительности '!Номер_платежа,DAY(Начало_кредита))
Name Дата_платежа: DATE(YEAR(Начало_кредита),MONTH(Начало_кредита)+'Диаграмма эластичности'!Номер_платежа,DAY(Начало_кредита))
Name Дата_платежа: DATE(YEAR(Начало_кредита),MONTH(Начало_кредита)+[0]!Номер_платежа,DAY(Начало_кредита))
Name Дата_платежа: DATE(YEAR(Начало_кредита),MONTH(Начало_кредита)+Номер_платежа,DAY(Начало_кредита))
Name Ежемесячный_платеж: -PMT(Процентная_ставка/12,Количество_платежей,Сумма_кредита)
Name Ежемесячный_платеж: -PMT(Процентная_ставка/12,Количество_платежей,Сумма_кредита)
Name Ежемесячный_платеж: -PMT(Процентная_ставка/12,Количество_платежей,Сумма_кредита)
Name Ежемесячный_платеж: -PMT(Процентная_ставка/12,Количество_платежей,Сумма_кредита)
Name Земнал: [3]Предпосылки!$E$72
Name Земнал: [4]Предпосылки!$E$72
Name Земнал: [5]Предпосылки!$E$72
Name КЗ_инж: [3]Предпосылки!$E$109
Name КЗ_инж: [4]Предпосылки!$E$109
Name КЗ_инж: [5]Предпосылки!$E$109
Name КЗ_ИТ: [3]Предпосылки!$E$108
Name КЗ_ИТ: [4]Предпосылки!$E$108
Name КЗ_ИТ: [5]Предпосылки!$E$108
Name КЗ_ком: [3]Предпосылки!$E$105
Name КЗ_ком: [4]Предпосылки!$E$105
Name КЗ_ком: [5]Предпосылки!$E$105
Name КЗ_охрана: [3]Предпосылки!$E$107
Name КЗ_охрана: [4]Предпосылки!$E$107
Name КЗ_охрана: [5]Предпосылки!$E$107
Name КЗ_проч_содерж: [3]Предпосылки!$E$110
Name КЗ_проч_содерж: [4]Предпосылки!$E$110
Name КЗ_проч_содерж: [5]Предпосылки!$E$110
Name КЗ_прочие: [3]Предпосылки!$E$111
Name КЗ_прочие: [4]Предпосылки!$E$111
Name КЗ_прочие: [5]Предпосылки!$E$111
Name КЗ_СВ: [3]Предпосылки!$E$103
Name КЗ_СВ: [4]Предпосылки!$E$103
Name КЗ_СВ: [5]Предпосылки!$E$103
Name КЗ_уборка: [3]Предпосылки!$E$106
Name КЗ_уборка: [4]Предпосылки!$E$106
Name КЗ_уборка: [5]Предпосылки!$E$106
Name КЗ_ФОТ: [3]Предпосылки!$E$102
Name КЗ_ФОТ: [4]Предпосылки!$E$102
Name КЗ_ФОТ: [5]Предпосылки!$E$102
Name Конечный_баланс: -FV(Процентная_ставка/12,'Анализ чувствительности '!Номер_платежа,-'Анализ чувствительности '!Ежемесячный_платеж,Сумма_кредита)
Name Конечный_баланс: -FV(Процентная_ставка/12,'Диаграмма эластичности'!Номер_платежа,-'Диаграмма эластичности'!Ежемесячный_платеж,Сумма_кредита)
Name Конечный_баланс: -FV(Процентная_ставка/12,[0]!Номер_платежа,-'ФинРез Кампус'!Ежемесячный_платеж,Сумма_кредита)
Name Конечный_баланс: -FV(Процентная_ставка/12,Номер_платежа,-Ежемесячный_платеж,Сумма_кредита)
Name Наценка_комаренда: [3]Предпосылки!$E$86
Name Наценка_комаренда: [4]Предпосылки!$E$86
Name Наценка_комаренда: [5]Предпосылки!$E$86
Name Наценка_рез: [3]Предпосылки!#REF!
Name Наценка_рез: [4]Предпосылки!#REF!
Name Начальный_баланс: -FV(Процентная_ставка/12,'Анализ чувствительности '!Номер_платежа-1,-'Анализ чувствительности '!Ежемесячный_платеж,Сумма_кредита)
Name Начальный_баланс: -FV(Процентная_ставка/12,'Диаграмма эластичности'!Номер_платежа-1,-'Диаграмма эластичности'!Ежемесячный_платеж,Сумма_кредита)
Name Начальный_баланс: -FV(Процентная_ставка/12,[0]!Номер_платежа-1,-'ФинРез Кампус'!Ежемесячный_платеж,Сумма_кредита)
Name Начальный_баланс: -FV(Процентная_ставка/12,Номер_платежа-1,-Ежемесячный_платеж,Сумма_кредита)
Name НДФЛ: [3]Предпосылки!$E$70
Name НДФЛ: [4]Предпосылки!$E$70

Sheet Паспорт
D3: Общие характеристики
C5: № п/п | D5: Наименование | E5: Значение
C6: 1 | D6: Параметры кампуса
C7: =C6+1 -> 2 | D7: Общие сведения
C8: =C7+1 -> 3 | D8: =[9]Предпосылки!$D$12 -> Научно-технологический образовательный кампус "Долина Ростеха" в г. Фрязино Московской обл.
C9: =C8+1 -> 4 | D9: Срок сдачи в эксплуатацию | E9: =[9]Предпосылки!E13 -> 49491 | G9: Источник данных - модель инфраструктуры
C10: =C9+1 -> 5 | D10: Общая площадь территорий | E10: =[9]Предпосылки!E14 -> 311600
C11: =C10+1 -> 6 | D11: Общая площадь зданий и сооружений | E11: =[9]Предпосылки!E15 -> 92000
C12: =C11+1 -> 7 | D12: учебные площади | E12: =[9]Предпосылки!E16 -> 19800
C13: =C12+1 -> 8 | D13: лабораторные площади | E13: =[9]Предпосылки!E17 -> 6800
C14: =C13+1 -> 9 | D14: офисные площади | E14: =[9]Предпосылки!E18 -> 2250
C15: =C14+1 -> 10 | D15: переговорные, коворкинги, конференц-залы | E15: =[9]Предпосылки!E19 -> 17160
C16: =C15+1 -> 11 | D16: производственные площади | E16: =[9]Предпосылки!E20 -> 8000
C17: =C16+1 -> 12 | D17: площади для размещения объектов здравоохранения | E17: =[9]Предпосылки!E21 -> 0
C18: =C17+1 -> 13 | D18: площади для размещения пунктов питания | E18: =[9]Предпосылки!E22 -> 960
C19: =C18+1 -> 14 | D19: площади спортивных объектов | E19: =[9]Предпосылки!E23 -> 1770.25
C20: =C19+1 -> 15 | D20: площади для размещения объектов проживания | E20: =[9]Предпосылки!E24 -> 18278.14
C21: =C20+1 -> 16 | D21: коммерческие площади свободного назначения | E21: =[9]Предпосылки!E25 -> 0
... C24: =C23+1 -> 19 | D24: прочие площади | E24: =[9]Предпосылки!E28 -> 12454.59
C25: 20 | D25: Распределение иной полезной площади
C26: 21 | D26: Использование и содержание головным ВУЗом | E26: =[9]Предпосылки!E30 -> 79545.41
C27: 22 | D27: Сдача в аренду | E27: =[9]Предпосылки!E31 -> 54545.41
C28: 23 | D28: Использование для ведения иной коммерческой деятельности | E28: =[9]Предпосылки!E32 -> 25000
C29: 26 | D29: Виды иной коммерческой деятельности
C30: 27 | D30: Оказание услуг питания | E30: =[9]Предпосылки!E34 -> Не реализуется
C31: 28 | D31: Торговля | E31: =[9]Предпосылки!E35 -> Не реализуется
C32: 29 | D32: Управление объектами размещенния (гостиницы, общежития) | E32: =[9]Предпосылки!E36 -> Реализуется
C33: 30 | D33: Деятельность по проведению мероприятий | E33: =[9]Предпосылки!E37 -> Не реализуется
C34: 31 | D34: Управление объектами спортивной инфраструктуры | E34: =[9]Предпосылки!E38 -> Не реализуется

Sheet ФинРез и инд-ры ВУЗ
AV2: 1 | AW2: 1 | AX2: 1 | AY2: 1 | AZ2: 1 | BA2: 1 | BB2: 1 | BC2: 1 | BD2: 1 | BE2: 1 | BF2: 1 | BG2: 1 | BH2: 1 | BI2: 1 | BJ2: 1 | BK2: 1 | BL2: 1 | BM2: 1 | BN2: 1 | BO2: 1 | BP2: 1 | DH2: 1 | DI2: 1 | DJ2: 1 | DK2: 1 | DL2: 1 | DM2: 1 | DN2: 1 | DO2: 1 | DP2: 1 | DQ2: 1 | DR2: 1 | DS2: 1 | DT2: 1 | DU2: 1 | DV2: 1 | DW2: 1 | DX2: 1 | DY2: 1 | DZ2: 1 | EA2: 1 | EB2: 1
D3: Индикаторы деятельности вузов | F3: МИРЭА — Российский технологический университет (РТУ МИРЭА)
F4: Сценарий 1 | AV4: Сценарий 1 | BR4: Сценарий 2 | DH4: Сценарий 1 | ED4: Дельта (сценарий 2 - сценарий 1)
C5: № п/п | D5: Наименование показателей | E5: ед. | F5: 2022 | G5: 2023 | H5: 2024 | I5: 2025 | J5: 2026 | K5: 2027 | L5: 2028 | M5: 2029 | N5: 2030 | O5: 2031 | P5: 2032 | Q5: 2033 | R5: 2034 | S5: 2035 | T5: 2036 | U5: 2037 | V5: 2038 | W5: 2039 | X5: 2040 | Y5: 2041 | Z5: 2042 | BQ5: Итого за период 2026-2042 гг | BR5: 2022 | BS5: 2023 | BT5: 2024 | BU5: 2025 | BV5: 2026 | BW5: 2027 | BX5: 2028 | BY5: 2029 | BZ5: 2030 | CA5: 2031 | CB5: 2032 | CC5: 2033 | CD5: 2034 | CE5: 2035 | CF5: 2036 | CG5: 2037 | CH5: 2038 | CI5: 2039 | CJ5: 2040 | CK5: 2041 | CL5: 2042 | EC5: Итого за период 2026-2042 гг | ED5: 2022 | EE5: 2023 | EF5: 2024 | EG5: 2025 | EH5: 2026 | EI5: 2027 | EJ5: 2028 | EK5: 2029 | EL5: 2030 | EM5: 2031 | EN5: 2032 | EO5: 2033 | EP5: 2034 | EQ5: 2035 | ER5: 2036 | ES5: 2037 | ET5: 2038 | EU5: 2039 | EV5: 2040 | EW5: 2041 | EX5: 2042 | EY5: Итого за период 2026-2042 гг
F6: факт | G6: факт | H6: факт | I6: план | J6: план | K6: план | L6: план | M6: план | N6: план | O6: план | P6: план | Q6: план | R6: план | S6: план | T6: план | U6: план | V6: план | W6: план | X6: план | Y6: план | Z6: план | BR6: факт | BS6: факт | BT6: факт | BU6: план | BV6: план | BW6: план | BX6: план | BY6: план | BZ6: план | CA6: план | CB6: план | CC6: план | CD6: план | CE6: план | CF6: план | CG6: план | CH6: план | CI6: план | CJ6: план | CK6: план | CL6: план | ED6: факт | EE6: факт | EF6: факт | EG6: план | EH6: план | EI6: план | EJ6: план | EK6: план | EL6: план | EM6: план | EN6: план | EO6: план | EP6: план | EQ6: план | ER6: план | ES6: план | ET6: план | EU6: план | EV6: план | EW6: план | EX6: план
D8: Финансовые показатели
C9: 1 | D9: ФИНАНСОВЫЙ РЕЗУЛЬТАТ КАМПУСА (интегрированный) | F9: =F10-F11-F12 -> 5539689.5 | G9: =G10-G11-G12 -> 6357827.8 | H9: =H10-H11-H12 -> 7564444.6 | I9: =I10-I11-I12 -> 8103936.4 | J9: =J10-J11-J12 -> 8519190.9 | K9: =K10-K11-K12 -> 8995587.1 | L9: =L10-L11-L12 -> 9480539.2 | M9: =M10-M11-M12 -> 9958076.7 | ... Z9: =Z10-Z11-Z12 -> 19749143 | BQ9: =BQ10-BQ11-BQ12 -> 2.2717526e+08 | BR9: =BR10-BR11-BR12 -> 5539689.5 | BS9: =BS10-BS11-BS12 -> 6357827.8 | BT9: =BT10-BT11-BT12 -> 7564444.6 | BU9: =BU10-BU11-BU12 -> 7953786 | BV9: =BV10-BV11-BV12 -> 8779454.4 | BW9: =BW10-BW11-BW12 -> 11860961 | BX9: =BX10-BX11-BX12 -> 11560327 | ... CL9: =CL10-CL11-CL12 -> 25388408 | EC9: =EC10-EC11-EC12 -> 3.1476351e+08 | ED9: =ED10-ED11-ED12 -> 0 | EE9: =EE10-EE11-EE12 -> 0 | EF9: =EF10-EF11-EF12 -> 0 | EG9: =EG10-EG11-EG12 -> 367624.03 | EH9: =EH10-EH11-EH12 -> 822670.37 | EI9: =EI10-EI11-EI12 -> 1183604.5 | EJ9: =EJ10-EJ11-EJ12 -> 1514961.6 | ... EY9: =EY10-EY11-EY12 -> 40055291
C10: 2 | D10: Доходы | F10: =F38 -> 10491307 | G10: =G38 -> 12413481 | H10: =H38 -> 15281575 | I10: =I38 -> 16541920 | J10: =J38 -> 17535322 | K10: =K38 -> 18604050 | L10: =L38 -> 19471726 | M10: =M38 -> 20345931 | ... Z10: =Z38 -> 37046659 | AA10: 844890.95 | AB10: 1540312.3 | AC10: 2978551.2 | AD10: 4875098.2 | AE10: 6884480 | AF10: 9062036.2 | AG10: 11419275 | AH10: 13933192 | AI10: 16634713 | AJ10: 19532618 | AK10: 22643126 | AL10: 25980160 | AM10: 29556966 | AN10: 33394567 | AO10: 37505010 | AP10: 41909414 | AQ10: 46625582 | AR10: 51675275 | AS10: 57082954 | AT10: 62870272 | AU10: 69061737 | AV10: =AA10=F10 -> FALSE | AW10: =AB10=G10 -> FALSE | AX10: =AC10=H10 -> FALSE | AY10: =AD10=I10 -> FALSE | AZ10: =AE10=J10 -> FALSE | BA10: =AF10=K10 -> FALSE | BB10: =AG10=L10 -> FALSE | BC10: =AH10=M10 -> FALSE | ... BP10: =AU10=Z10 -> FALSE | BQ10: =SUM(J10:Z10) -> 4.4581021e+08 | BR10: =BR38 -> 10491307 | BS10: =BS38 -> 12413481 | BT10: =BT38 -> 15281575 | BU10: =BU38 -> 16798888 | BV10: =BV38 -> 18753447 | BW10: =BW38 -> 22555695 | BX10: =BX38 -> 22784137 | BY10: =BY38 -> 23185804 | ... CL10: =CL38 -> 45147510 | CM10: 844890.95 | CN10: 1540312.3 | CO10: 2978551.2 | CP10: 4732514.5 | CQ10: 7235055.3 | CR10: 11362033 | CS10: 15446989 | CT10: 19479870 | CU10: 30243615 | CV10: 41475722 | CW10: 51739482 | CX10: 62750361 | CY10: 70149867 | CZ10: 78137154 | DA10: 86569339 | DB10: 95347432 | DC10: 1.0445796e+08 | DD10: 1.1325971e+08 | DE10: 1.2310187e+08 | DF10: 1.333393e+08 | DG10: 1.4400058e+08 | DH10: =CM10=BR10 -> FALSE | DI10: =CN10=BS10 -> FALSE | DJ10: =CO10=BT10 -> FALSE | DK10: =CP10=BU10 -> FALSE | DL10: =CQ10=BV10 -> FALSE | DM10: =CR10=BW10 -> FALSE | DN10: =CS10=BX10 -> FALSE | DO10: =CT10=BY10 -> FALSE | ... EB10: =DG10=CL10 -> FALSE | EC10: =SUM(BV10:CL10) -> 5.6283073e+08 | ED10: =ED14+ED19+'ФинРез Кампус'!F210 -> 0 | EE10: =EE14+EE19+'ФинРез Кампус'!G210 -> 0 | EF10: =EF14+EF19+'ФинРез Кампус'!H210 -> 0 | EG10: =EG14+EG19+'ФинРез Кампус'!I210 -> 774741.98 | EH10: =EH14+EH19+'ФинРез Кампус'!J210 -> 1780531.5 | EI10: =EI14+EI19+'ФинРез Кампус'!K210 -> 2269875.5 | EJ10: =EJ14+EJ19+'ФинРез Кампус'!L210 -> 2747586 | EK10: =EK14+EK19+'ФинРез Кампус'!M210 -> 2996662.4 | ... EX10: =EX14+EX19+'ФинРез Кампус'!Z210 -> 6503951.5 | EY10: =SUM(EH10:EX10) -> 72273351
C11: 3 | D11: Переменные расходы (ФОТ основного персонала, матзапасы, НМА, соисполнители) | F11: =F43 -> 4951617.5 | G11: =G43 -> 6055653 | H11: =H43 -> 7717130.8 | I11: =I43 -> 8437984 | J11: =J43 -> 9016131.3 | K11: =K43 -> 9608462.5 | L11: =L43 -> 9991186.5 | M11: =M43 -> 10387854 | ... Z11: =Z43 -> 17297516 | AA11: 844890.95 | AB11: 695421.31 | AC11: 1438239 | AD11: 1896547 | AE11: 2009381.8 | AF11: 2177556.2 | AG11: 2357238.6 | AH11: 2513917 | AI11: 2701521.6 | AJ11: 2897905.1 | AK11: 3110508 | AL11: 3337033 | AM11: 3576806.2 | AN11: 3837601.1 | AO11: 4110443.2 | AP11: 4404403.8 | AQ11: 4716168.1 | AR11: 5049693 | AS11: 5407679 | AT11: 5787317.9 | AU11: 6191465.4 | AV11: =AA11=F11 -> FALSE | AW11: =AB11=G11 -> FALSE | AX11: =AC11=H11 -> FALSE | AY11: =AD11=I11 -> FALSE | AZ11: =AE11=J11 -> FALSE | BA11: =AF11=K11 -> FALSE | BB11: =AG11=L11 -> FALSE | BC11: =AH11=M11 -> FALSE | ... BP11: =AU11=Z11 -> FALSE | BQ11: =SUM(J11:Z11) -> 2.1863495e+08 | BR11: =BR43 -> 4951617.5 | BS11: =BS43 -> 6055653 | BT11: =BT43 -> 7717130.8 | BU11: =BU43 -> 8845102 | BV11: =BV43 -> 9973992.5 | BW11: =BW43 -> 10694734 | BX11: =BX43 -> 11223811 | BY11: =BY43 -> 11701892 | ... CL11: =CL43 -> 19759102 | CM11: 844890.95 | CN11: 695421.31 | CO11: 1438239 | CP11: 1753963.3 | CQ11: 2502540.8 | CR11: 4126978.2 | CS11: 4084956 | CT11: 4032880.6 | CU11: 10763745 | CV11: 11232107 | CW11: 10263760 | CX11: 11010879 | CY11: 7399506 | CZ11: 7987286.4 | DA11: 8432185.4 | DB11: 8778092.9 | DC11: 9110524 | DD11: 8801754.1 | DE11: 9842155.6 | DF11: 10237432 | DG11: 10661278 | DH11: =CM11=BR11 -> FALSE | DI11: =CN11=BS11 -> FALSE | DJ11: =CO11=BT11 -> FALSE | DK11: =CP11=BU11 -> FALSE | DL11: =CQ11=BV11 -> FALSE | DM11: =CR11=BW11 -> FALSE | DN11: =CS11=BX11 -> FALSE | DO11: =CT11=BY11 -> FALSE | ... EB11: =DG11=CL11 -> FALSE | EC11: =SUM(BV11:CL11) -> 2.4754995e+08 | ED11: =ED15+ED20+'ФинРез Кампус'!F212 -> 0 | EE11: =EE15+EE20+'ФинРез Кампус'!G212 -> 0 | EF11: =EF15+EF20+'ФинРез Кампус'!H212 -> 0 | EG11: =EG15+EG20+'ФинРез Кампус'!I212 -> 407117.95 | EH11: =EH15+EH20+'ФинРез Кампус'!J212 -> 957861.17 | EI11: =EI15+EI20+'ФинРез Кампус'!K212 -> 1086271.1 | EJ11: =EJ15+EJ20+'ФинРез Кампус'!L212 -> 1232624.4 | EK11: =EK15+EK20+'ФинРез Кампус'!M212 -> 1314038.1 | ... EX11: =EX15+EX20+'ФинРез Кампус'!Z212 -> 2547854.2 | EY11: =SUM(EH11:EX11) -> 29486620
C12: 5 | D12: Постоянные расходы (кампус) | AA12: -108964.17 | AB12: -363566.02 | AC12: -143885.64 | AD12: 243226.76 | AE12: 289928.75 | AF12: 389325.07 | AG12: 497478.17 | AH12: 579766.15 | AI12: 690004.77 | AJ12: 805927.57 | AK12: 934851.42 | AL12: 1074350.2 | AM12: 1223616 | AN12: 1390283.3 | AO12: 1565232.7 | AP12: 1757384.9 | AQ12: 1963268.4 | AR12: 2186677.3 | AS12: 2430142.7 | AT12: 2690680.1 | AU12: 2970962.1 | AV12: =AA12=F12 -> FALSE | AW12: =AB12=G12 -> FALSE | AX12: =AC12=H12 -> FALSE | AY12: =AD12=I12 -> FALSE | AZ12: =AE12=J12 -> FALSE | BA12: =AF12=K12 -> FALSE | BB12: =AG12=L12 -> FALSE | BC12: =AH12=M12 -> FALSE | ... BP12: =AU12=Z12 -> FALSE | BR12: =ED12 -> 0 | BS12: =EE12 -> 0 | BT12: =EF12 -> 0 | BU12: =EG12 -> 0 | BV12: =EH12 -> 0 | BW12: =EI12 -> 0 | BX12: =EJ12 -> 0 | BY12: =EK12 -> 0 | ... CF12: =ER12 -> 355344.12 | CG12: =EZ12 -> 0 | CH12: =FA12 -> 0 | CI12: =FB12 -> 0 | CJ12: =FC12 -> 0 | CK12: =FD12 -> 0 | CL12: =FE12 -> 0 | CM12: -108964.17 | CN12: -363566.02 | CO12: -143885.64 | CP12: 100643.09 | CQ12: 783087.73 | CR12: 2338747 | CS12: 2225195.6 | CT12: 2223107.7 | CU12: 2100269.7 | CV12: 2222092.4 | CW12: 3291597.6 | CX12: 3759830.2 | CY12: 3946315.8 | CZ12: 5539968.6 | DA12: 5886974.9 | DB12: 6131073.9 | DC12: 6357624.3 | DD12: 5938738.4 | DE12: 6864619.2 | DF12: 7140794 | DG12: 7440775 | DH12: =CM12=BR12 -> FALSE | DI12: =CN12=BS12 -> FALSE | DJ12: =CO12=BT12 -> FALSE | DK12: =CP12=BU12 -> FALSE | DL12: =CQ12=BV12 -> FALSE | DM12: =CR12=BW12 -> FALSE | DN12: =CS12=BX12 -> FALSE | DO12: =CT12=BY12 -> FALSE | ... EB12: =DG12=CL12 -> FALSE | EC12: =SUM(BV12:CL12) -> 517265.22 | ED12: ='ФинРез Кампус'!F7 -> 0 | EE12: ='ФинРез Кампус'!G7 -> 0 | EF12: ='ФинРез Кампус'!H7 -> 0 | EG12: ='ФинРез Кампус'!I7 -> 0 | EH12: ='ФинРез Кампус'!J7 -> 0 | EI12: ='ФинРез Кампус'!K7 -> 0 | EJ12: ='ФинРез Кампус'!L7 -> 0 | EK12: ='ФинРез Кампус'!M7 -> 0 | ... EX12: ='ФинРез Кампус'!Z7 -> 410954.51 | EY12: =SUM(EH12:EX12) -> 2731439.7
D13: Образование | AV13: =AA13=F13 -> TRUE | AW13: =AB13=G13 -> TRUE | AX13: =AC13=H13 -> TRUE | AY13: =AD13=I13 -> TRUE | AZ13: =AE13=J13 -> TRUE | BA13: =AF13=K13 -> TRUE | BB13: =AG13=L13 -> TRUE | BC13: =AH13=M13 -> TRUE | ... BP13: =AU13=Z13 -> TRUE | DH13: =CM13=BR13 -> TRUE | DI13: =CN13=BS13 -> TRUE | DJ13: =CO13=BT13 -> TRUE | DK13: =CP13=BU13 -> TRUE | DL13: =CQ13=BV13 -> TRUE | DM13: =CR13=BW13 -> TRUE | DN13: =CS13=BX13 -> TRUE | DO13: =CT13=BY13 -> TRUE | ... EB13: =DG13=CL13 -> TRUE | ED13: =ED14-ED15-ED16 -> 0 | EE13: =EE14-EE15-EE16 -> 0 | EF13: =EF14-EF15-EF16 -> 0 | EG13: =EG14-EG15-EG16 -> 367011.76 | EH13: =EH14-EH15-EH16 -> 782713.72 | EI13: =EI14-EI15-EI16 -> 1143020.3 | EJ13: =EJ14-EJ15-EJ16 -> 1469945.2 | EK13: =EK14-EK15-EK16 -> 1636817.1 | ... EX13: =EX14-EX15-EX16 -> 2016699
C14: 6 | D14: Доходы | E14: тыс. руб. | F14: ='[10]Данные для переноса'!F14 -> 8984824.4 | G14: ='[10]Данные для переноса'!G14 -> 10045646 | H14: ='[10]Данные для переноса'!H14 -> 11942291 | I14: ='[10]Данные для переноса'!I14 -> 12450116 | J14: ='[10]Данные для переноса'!J14 -> 13279852 | K14: ='[10]Данные для переноса'!K14 -> 14178366 | L14: ='[10]Данные для переноса'!L14 -> 14869021 | M14: ='[10]Данные для переноса'!M14 -> 15559124 | ... Z14: ='[10]Данные для переноса'!Z14 -> 29076364 | AA14: 8984824.4 | AB14: 10045646 | AC14: 11942291 | AD14: 12450116 | AE14: 13279852 | AF14: 14178366 | AG14: 14869021 | AH14: 15559124 | AI14: 16308490 | AJ14: 17093187 | AK14: 17922049 | AL14: 18794253 | AM14: 19710689 | AN14: 20680802 | AO14: 21697375 | AP14: 22771346 | AQ14: 23901377 | AR14: 25093528 | AS14: 26352732 | AT14: 27678551 | AU14: 29076364 | AV14: =AA14=F14 -> TRUE | AW14: =AB14=G14 -> TRUE | AX14: =AC14=H14 -> TRUE | AY14: =AD14=I14 -> TRUE | AZ14: =AE14=J14 -> TRUE | BA14: =AF14=K14 -> TRUE | BB14: =AG14=L14 -> TRUE | BC14: =AH14=M14 -> TRUE | ... BP14: =AU14=Z14 -> TRUE | BQ14: =SUM(J14:Z14) -> 3.449671e+08 | BR14: ='[10]Данные для переноса'!AB14 -> 8984824.4 | BS14: ='[10]Данные для переноса'!AC14 -> 10045646 | BT14: ='[10]Данные для переноса'!AD14 -> 11942291 | BU14: ='[10]Данные для переноса'!AE14 -> 13217205 | BV14: ='[10]Данные для переноса'!AF14 -> 14560925 | BW14: ='[10]Данные для переноса'!AG14 -> 15940940 | BX14: ='[10]Данные для переноса'!AH14 -> 17053902 | BY14: ='[10]Данные для переноса'!AI14 -> 17983197 | ... CL14: ='[10]Данные для переноса'!AV14 -> 32897557 | CM14: 8984824.4 | CN14: 10045646 | CO14: 11942291 | CP14: 13217205 | CQ14: 14560925 | CR14: 15940940 | CS14: 17053902 | CT14: 17983197 | CU14: 18827670 | CV14: 19698717 | CW14: 20615205 | CX14: 21579163 | CY14: 22592107 | CZ14: 23658905 | DA14: 24775829 | DB14: 25975642 | DC14: 27220943 | DD14: 28528405 | DE14: 29914885 | DF14: 31362727 | DG14: 32897557 | DH14: =CM14=BR14 -> TRUE | DI14: =CN14=BS14 -> TRUE | DJ14: =CO14=BT14 -> TRUE | DK14: =CP14=BU14 -> TRUE | DL14: =CQ14=BV14 -> TRUE | DM14: =CR14=BW14 -> TRUE | DN14: =CS14=BX14 -> TRUE | DO14: =CT14=BY14 -> TRUE | ... EB14: =DG14=CL14 -> TRUE | EC14: =SUM(BV14:CL14) -> 3.9318672e+08 | ED14: =BR14-F14 -> 0 | EE14: =BS14-G14 -> 0 | EF14: =BT14-H14 -> 0 | EG14: =BU14-I14 -> 767088.6 | EH14: =BV14-J14 -> 1281073.5 | EI14: =BW14-K14 -> 1762573.6 | EJ14: =BX14-L14 -> 2184880.8 | EK14: =BY14-M14 -> 2424073.7 | ... EX14: =CL14-Z14 -> 3821193.4 | EY14: =SUM(EH14:EX14) -> 48219616
C15: 7 | D15: Переменные расходы (ФОТ основного персонала, матзапасы, НМА, соисполнители) | E15: тыс. руб. | F15: ='[10]Данные для переноса'!F15 -> 3882674.3 | G15: ='[10]Данные для переноса'!G15 -> 4550089.5 | H15: ='[10]Данные для переноса'!H15 -> 5312139.2 | I15: ='[10]Данные для переноса'!I15 -> 5811953.8 | J15: ='[10]Данные для переноса'!J15 -> 6316299.1 | K15: ='[10]Данные для переноса'!K15 -> 6822832.9 | L15: ='[10]Данные для переноса'!L15 -> 7094131.8 | M15: ='[10]Данные для переноса'!M15 -> 7374917.2 | ... Z15: ='[10]Данные для переноса'!Z15 -> 12280755 | AA15: 3882674.3 | AB15: 4550089.5 | AC15: 5312139.2 | AD15: 5811953.8 | AE15: 6316299.1 | AF15: 6822832.9 | AG15: 7094131.8 | AH15: 7374917.2 | AI15: 7669950.5 | AJ15: 7976788.2 | AK15: 8295902.6 | AL15: 8627785 | AM15: 8972946.6 | AN15: 9331918.7 | AO15: 9705254.1 | AP15: 10093528 | AQ15: 10497338 | AR15: 10917305 | AS15: 11354078 | AT15: 11808328 | AU15: 12280755 | AV15: =AA15=F15 -> TRUE | AW15: =AB15=G15 -> TRUE | AX15: =AC15=H15 -> TRUE | AY15: =AD15=I15 -> TRUE | AZ15: =AE15=J15 -> TRUE | BA15: =AF15=K15 -> TRUE | BB15: =AG15=L15 -> TRUE | BC15: =AH15=M15 -> TRUE | ... BP15: =AU15=Z15 -> TRUE | BQ15: =SUM(J15:Z15) -> 1.5514006e+08 | BR15: ='[10]Данные для переноса'!AB15 -> 3882674.3 | BS15: ='[10]Данные для переноса'!AC15 -> 4550089.5 | BT15: ='[10]Данные для переноса'!AD15 -> 5312139.2 | BU15: ='[10]Данные для переноса'!AE15 -> 6212030.6 | BV15: ='[10]Данные для переноса'!AF15 -> 6814658.8 | BW15: ='[10]Данные для переноса'!AG15 -> 7442386.3 | BX15: ='[10]Данные для переноса'!AH15 -> 7809067.4 | BY15: ='[10]Данные для переноса'!AI15 -> 8162173.7 | ... CL15: ='[10]Данные для переноса'!AV15 -> 14085249 | CM15: 3882674.3 | CN15: 4550089.5 | CO15: 5312139.2 | CP15: 6212030.6 | CQ15: 6814658.8 | CR15: 7442386.3 | CS15: 7809067.4 | CT15: 8162173.7 | CU15: 8512533.7 | CV15: 8876864.9 | CW15: 9257140 | CX15: 9654068.5 | CY15: 10068391 | CZ15: 10497843 | DA15: 10945544 | DB15: 11423650 | DC15: 11914338 | DD15: 12422177 | DE15: 12955851 | DF15: 13506428 | DG15: 14085249 | DH15: =CM15=BR15 -> TRUE | DI15: =CN15=BS15 -> TRUE | DJ15: =CO15=BT15 -> TRUE | DK15: =CP15=BU15 -> TRUE | DL15: =CQ15=BV15 -> TRUE | DM15: =CR15=BW15 -> TRUE | DN15: =CS15=BX15 -> TRUE | DO15: =CT15=BY15 -> TRUE | ... EB15: =DG15=CL15 -> TRUE | EC15: =SUM(BV15:CL15) -> 1.7434836e+08 | ED15: =BR15-F15 -> 0 | EE15: =BS15-G15 -> 0 | EF15: =BT15-H15 -> 0 | EG15: =BU15-I15 -> 400076.84 | EH15: =BV15-J15 -> 498359.74 | EI15: =BW15-K15 -> 619553.31 | EJ15: =BX15-L15 -> 714935.6 | EK15: =BY15-M15 -> 787256.52 | ... EX15: =CL15-Z15 -> 1804494.4 | EY15: =SUM(EH15:EX15) -> 19208307
C16: 8 | D16: Постоянные расходы | E16: тыс. руб. | AV16: =AA16=F16 -> TRUE | AW16: =AB16=G16 -> TRUE | AX16: =AC16=H16 -> TRUE | AY16: =AD16=I16 -> TRUE | AZ16: =AE16=J16 -> TRUE | BA16: =AF16=K16 -> TRUE | BB16: =AG16=L16 -> TRUE | BC16: =AH16=M16 -> TRUE | ... BP16: =AU16=Z16 -> TRUE | DH16: =CM16=BR16 -> TRUE | DI16: =CN16=BS16 -> TRUE | DJ16: =CO16=BT16 -> TRUE | DK16: =CP16=BU16 -> TRUE | DL16: =CQ16=BV16 -> TRUE | DM16: =CR16=BW16 -> TRUE | DN16: =CS16=BX16 -> TRUE | DO16: =CT16=BY16 -> TRUE | ... EB16: =DG16=CL16 -> TRUE | ED16: ='ФинРез Кампус'!F23 -> 0 | EE16: ='ФинРез Кампус'!G23 -> 0 | EF16: ='ФинРез Кампус'!H23 -> 0 | EG16: ='ФинРез Кампус'!I23 -> 0 | EH16: ='ФинРез Кампус'!J23 -> 0 | EI16: ='ФинРез Кампус'!K23 -> 0 | EJ16: ='ФинРез Кампус'!L23 -> 0 | EK16: ='ФинРез Кампус'!M23 -> 0 | ... EX16: ='ФинРез Кампус'!Z23 -> 0
C17: 9 | D17: Инвестиционные расходы (включая приобретение основных средств) | E17: тыс. руб. | F17: ='[10]Данные для переноса'!F16 -> 481773.37 | G17: ='[10]Данные для переноса'!G16 -> 580219.16 | H17: ='[10]Данные для переноса'!H16 -> 873016.36 | I17: ='[10]Данные для переноса'!I16 -> 912302.1 | J17: ='[10]Данные для переноса'!J16 -> 948794.18 | K17: ='[10]Данные для переноса'!K16 -> 986745.95 | L17: ='[10]Данные для переноса'!L16 -> 1026215.8 | M17: ='[10]Данные для переноса'!M16 -> 1067264.4 | ... Z17: ='[10]Данные для переноса'!Z16 -> 1777073.7 | AA17: 481773.37 | AB17: 580219.16 | AC17: 873016.36 | AD17: 912302.1 | AE17: 948794.18 | AF17: 986745.95 | AG17: 1026215.8 | AH17: 1067264.4 | AI17: 1109955 | AJ17: 1154353.2 | AK17: 1200527.3 | AL17: 1248548.4 | AM17: 1298490.4 | AN17: 1350430 | AO17: 1404447.2 | AP17: 1460625.1 | AQ17: 1519050.1 | AR17: 1579812.1 | AS17: 1643004.5 | AT17: 1708724.7 | AU17: 1777073.7 | AV17: =AA17=F17 -> TRUE | AW17: =AB17=G17 -> TRUE | AX17: =AC17=H17 -> TRUE | AY17: =AD17=I17 -> TRUE | AZ17: =AE17=J17 -> TRUE | BA17: =AF17=K17 -> TRUE | BB17: =AG17=L17 -> TRUE | BC17: =AH17=M17 -> TRUE | ... BP17: =AU17=Z17 -> TRUE | BQ17: =SUM(J17:Z17) -> 22484062 | BR17: ='[10]Данные для переноса'!AB16 -> 481773.37 | BS17: ='[10]Данные для переноса'!AC16 -> 580219.16 | BT17: ='[10]Данные для переноса'!AD16 -> 873016.36 | BU17: ='[10]Данные для переноса'!AE16 -> 912302.1 | BV17: ='[10]Данные для переноса'!AF16 -> 948794.18 | BW17: ='[10]Данные для переноса'!AG16 -> 986745.95 | BX17: ='[10]Данные для переноса'!AH16 -> 1026215.8 | BY17: ='[10]Данные для переноса'!AI16 -> 1067264.4 | ... CL17: ='[10]Данные для переноса'!AV16 -> 1777073.7 | CM17: 481773.37 | CN17: 580219.16 | CO17: 873016.36 | CP17: 912302.1 | CQ17: 948794.18 | CR17: 986745.95 | CS17: 1026215.8 | CT17: 1067264.4 | CU17: 1109955 | CV17: 1154353.2 | CW17: 1200527.3 | CX17: 1248548.4 | CY17: 1298490.4 | CZ17: 1350430 | DA17: 1404447.2 | DB17: 1460625.1 | DC17: 1519050.1 | DD17: 1579812.1 | DE17: 1643004.5 | DF17: 1708724.7 | DG17: 1777073.7 | DH17: =CM17=BR17 -> TRUE | DI17: =CN17=BS17 -> TRUE | DJ17: =CO17=BT17 -> TRUE | DK17: =CP17=BU17 -> TRUE | DL17: =CQ17=BV17 -> TRUE | DM17: =CR17=BW17 -> TRUE | DN17: =CS17=BX17 -> TRUE | DO17: =CT17=BY17 -> TRUE | ... EB17: =DG17=CL17 -> TRUE | EC17: =SUM(BV17:CL17) -> 22484062 | ED17: =BR17-F17 -> 0 | EE17: =BS17-G17 -> 0 | EF17: =BT17-H17 -> 0 | EG17: =BU17-I17 -> 0 | EH17: =BV17-J17 -> 0 | EI17: =BW17-K17 -> 0 | EJ17: =BX17-L17 -> 0 | EK17: =BY17-M17 -> 0 | ... EX17: =CL17-Z17 -> 0 | EY17: =SUM(EH17:EX17) -> 0
D18: Наука | AV18: =AA18=F18 -> TRUE | AW18: =AB18=G18 -> TRUE | AX18: =AC18=H18 -> TRUE | AY18: =AD18=I18 -> TRUE | AZ18: =AE18=J18 -> TRUE | BA18: =AF18=K18 -> TRUE | BB18: =AG18=L18 -> TRUE | BC18: =AH18=M18 -> TRUE | ... BP18: =AU18=Z18 -> TRUE | DH18: =CM18=BR18 -> TRUE | DI18: =CN18=BS18 -> TRUE | DJ18: =CO18=BT18 -> TRUE | DK18: =CP18=BU18 -> TRUE | DL18: =CQ18=BV18 -> TRUE | DM18: =CR18=BW18 -> TRUE | DN18: =CS18=BX18 -> TRUE | DO18: =CT18=BY18 -> TRUE | ... EB18: =DG18=CL18 -> TRUE | ED18: =ED19-ED20-ED21 -> 0 | EE18: =EE19-EE20-EE21 -> 0 | EF18: =EF19-EF20-EF21 -> 0 | EG18: =EG19-EG20-EG21 -> 612.27064 | EH18: =EH19-EH20-EH21 -> 39956.646 | EI18: =EI19-EI20-EI21 -> 40584.153 | EJ18: =EJ19-EJ20-EJ21 -> 45016.417 | EK18: =EK19-EK20-EK21 -> 45807.097 | ... EX18: =EX19-EX20-EX21 -> 57138.351
C19: 9 | D19: Доходы | E19: тыс. руб. | F19: ='[10]Данные для переноса'!F18 -> 1171701.4 | G19: ='[10]Данные для переноса'!G18 -> 1960113.9 | H19: ='[10]Данные для переноса'!H18 -> 2636185 | I19: ='[10]Данные для переноса'!I18 -> 2854380.7 | J19: ='[10]Данные для переноса'!J18 -> 2934600.2 | K19: ='[10]Данные для переноса'!K18 -> 3027858.2 | L19: ='[10]Данные для переноса'!L18 -> 3148972.5 | M19: ='[10]Данные для переноса'!M18 -> 3274931.4 | ... Z19: ='[10]Данные для переноса'!Z18 -> 5453001.5 | AA19: 1171701.4 | AB19: 1960113.9 | AC19: 2636185 | AD19: 2854380.7 | AE19: 2934600.2 | AF19: 3027858.2 | AG19: 3148972.5 | AH19: 3274931.4 | AI19: 3405928.7 | AJ19: 3542165.8 | AK19: 3683852.5 | AL19: 3831206.6 | AM19: 3984454.8 | AN19: 4143833 | AO19: 4309586.3 | AP19: 4481969.8 | AQ19: 4661248.6 | AR19: 4847698.5 | AS19: 5041606.5 | AT19: 5243270.7 | AU19: 5453001.5 | AV19: =AA19=F19 -> TRUE | AW19: =AB19=G19 -> TRUE | AX19: =AC19=H19 -> TRUE | AY19: =AD19=I19 -> TRUE | AZ19: =AE19=J19 -> TRUE | BA19: =AF19=K19 -> TRUE | BB19: =AG19=L19 -> TRUE | BC19: =AH19=M19 -> TRUE | ... BP19: =AU19=Z19 -> TRUE | BQ19: =SUM(J19:Z19) -> 69016186 | BR19: ='[10]Данные для переноса'!AB18 -> 1171701.4 | BS19: ='[10]Данные для переноса'!AC18 -> 1960113.9 | BT19: ='[10]Данные для переноса'!AD18 -> 2636185 | BU19: ='[10]Данные для переноса'!AE18 -> 2862034 | BV19: ='[10]Данные для переноса'!AF18 -> 3434058.3 | BW19: ='[10]Данные для переноса'!AG18 -> 3535160.1 | BX19: ='[10]Данные для переноса'!AH18 -> 3711677.7 | BY19: ='[10]Данные для переноса'!AI18 -> 3847520.1 | ... CL19: ='[10]Данные для переноса'!AV18 -> 6167230.9 | CM19: 1171701.4 | CN19: 1960113.9 | CO19: 2636185 | CP19: 2862034 | CQ19: 3434058.3 | CR19: 3535160.1 | CS19: 3711677.7 | CT19: 3847520.1 | CU19: 3988543.7 | CV19: 4134950.7 | CW19: 4286951.3 | CX19: 4444763.9 | CY19: 4608615.8 | CZ19: 4778742.9 | DA19: 4955390.8 | DB19: 5138814.6 | DC19: 5329279.5 | DD19: 5527061.2 | DE19: 5732446.4 | DF19: 5945733 | DG19: 6167230.9 | DH19: =CM19=BR19 -> TRUE | DI19: =CN19=BS19 -> TRUE | DJ19: =CO19=BT19 -> TRUE | DK19: =CP19=BU19 -> TRUE | DL19: =CQ19=BV19 -> TRUE | DM19: =CR19=BW19 -> TRUE | DN19: =CS19=BX19 -> TRUE | DO19: =CT19=BY19 -> TRUE | ... EB19: =DG19=CL19 -> TRUE | EC19: =SUM(BV19:CL19) -> 79566941 | ED19: =BR19-F19 -> 0 | EE19: =BS19-G19 -> 0 | EF19: =BT19-H19 -> 0 | EG19: =BU19-I19 -> 7653.3831 | EH19: =BV19-J19 -> 499458.08 | EI19: =BW19-K19 -> 507301.91 | EJ19: =BX19-L19 -> 562705.22 | EK19: =BY19-M19 -> 572588.71 | ... EX19: =CL19-Z19 -> 714229.39 | EY19: =SUM(EH19:EX19) -> 10550755
C20: 10 | D20: Переменные расходы (ФОТ основного персонала, матзапасы, НМА, соисполнители) | E20: тыс. руб. | F20: ='[10]Данные для переноса'!F19 -> 1068943.2 | G20: ='[10]Данные для переноса'!G19 -> 1505563.5 | H20: ='[10]Данные для переноса'!H19 -> 2404991.6 | I20: ='[10]Данные для переноса'!I19 -> 2626030.2 | J20: ='[10]Данные для переноса'!J19 -> 2699832.2 | K20: ='[10]Данные для переноса'!K19 -> 2785629.5 | L20: ='[10]Данные для переноса'!L19 -> 2897054.7 | M20: ='[10]Данные для переноса'!M19 -> 3012936.9 | ... Z20: ='[10]Данные для переноса'!Z19 -> 5016761.4 | AA20: 1068943.2 | AB20: 1505563.5 | AC20: 2404991.6 | AD20: 2626030.2 | AE20: 2699832.2 | AF20: 2785629.5 | AG20: 2897054.7 | AH20: 3012936.9 | AI20: 3133454.4 | AJ20: 3258792.6 | AK20: 3389144.3 | AL20: 3524710 | AM20: 3665698.4 | AN20: 3812326.4 | AO20: 3964819.4 | AP20: 4123412.2 | AQ20: 4288348.7 | AR20: 4459882.6 | AS20: 4638277.9 | AT20: 4823809.1 | AU20: 5016761.4 | AV20: =AA20=F20 -> TRUE | AW20: =AB20=G20 -> TRUE | AX20: =AC20=H20 -> TRUE | AY20: =AD20=I20 -> TRUE | AZ20: =AE20=J20 -> TRUE | BA20: =AF20=K20 -> TRUE | BB20: =AG20=L20 -> TRUE | BC20: =AH20=M20 -> TRUE | ... BP20: =AU20=Z20 -> TRUE | BQ20: =SUM(J20:Z20) -> 63494891 | BR20: ='[10]Данные для переноса'!AB19 -> 1068943.2 | BS20: ='[10]Данные для переноса'!AC19 -> 1505563.5 | BT20: ='[10]Данные для переноса'!AD19 -> 2404991.6 | BU20: ='[10]Данные для переноса'!AE19 -> 2633071.3 | BV20: ='[10]Данные для переноса'!AF19 -> 3159333.6 | BW20: ='[10]Данные для переноса'!AG19 -> 3252347.3 | BX20: ='[10]Данные для переноса'!AH19 -> 3414743.5 | BY20: ='[10]Данные для переноса'!AI19 -> 3539718.5 | ... CL20: ='[10]Данные для переноса'!AV19 -> 5673852.5 | CM20: 1068943.2 | CN20: 1505563.5 | CO20: 2404991.6 | CP20: 2633071.3 | CQ20: 3159333.6 | CR20: 3252347.3 | CS20: 3414743.5 | CT20: 3539718.5 | CU20: 3669460.2 | CV20: 3804154.7 | CW20: 3943995.2 | CX20: 4089182.8 | CY20: 4239926.5 | CZ20: 4396443.5 | DA20: 4558959.6 | DB20: 4727709.4 | DC20: 4902937.1 | DD20: 5084896.3 | DE20: 5273850.7 | DF20: 5470074.4 | DG20: 5673852.5 | DH20: =CM20=BR20 -> TRUE | DI20: =CN20=BS20 -> TRUE | DJ20: =CO20=BT20 -> TRUE | DK20: =CP20=BU20 -> TRUE | DL20: =CQ20=BV20 -> TRUE | DM20: =CR20=BW20 -> TRUE | DN20: =CS20=BX20 -> TRUE | DO20: =CT20=BY20 -> TRUE | ... EB20: =DG20=CL20 -> TRUE | EC20: =SUM(BV20:CL20) -> 73201586 | ED20: =BR20-F20 -> 0 | EE20: =BS20-G20 -> 0 | EF20: =BT20-H20 -> 0 | EG20: =BU20-I20 -> 7041.1124 | EH20: =BV20-J20 -> 459501.43 | EI20: =BW20-K20 -> 466717.76 | EJ20: =BX20-L20 -> 517688.8 | EK20: =BY20-M20 -> 526781.61 | ... EX20: =CL20-Z20 -> 657091.04 | EY20: =SUM(EH20:EX20) -> 9706695
C21: 12 | D21: Постоянные расходы | E21: тыс. руб. | AV21: =AA21=F21 -> TRUE | AW21: =AB21=G21 -> TRUE | AX21: =AC21=H21 -> TRUE | AY21: =AD21=I21 -> TRUE | AZ21: =AE21=J21 -> TRUE | BA21: =AF21=K21 -> TRUE | BB21: =AG21=L21 -> TRUE | BC21: =AH21=M21 -> TRUE | ... BP21: =AU21=Z21 -> TRUE | BQ21: =SUM(J21:Z21) -> 0 | DH21: =CM21=BR21 -> TRUE | DI21: =CN21=BS21 -> TRUE | DJ21: =CO21=BT21 -> TRUE | DK21: =CP21=BU21 -> TRUE | DL21: =CQ21=BV21 -> TRUE | DM21: =CR21=BW21 -> TRUE | DN21: =CS21=BX21 -> TRUE | DO21: =CT21=BY21 -> TRUE | ... EB21: =DG21=CL21 -> TRUE | EC21: =SUM(BV21:CL21) -> 0 | ED21: ='ФинРез Кампус'!F90 -> 0 | EE21: ='ФинРез Кампус'!G90 -> 0 | EF21: ='ФинРез Кампус'!H90 -> 0 | EG21: ='ФинРез Кампус'!I90 -> 0 | EH21: ='ФинРез Кампус'!J90 -> 0 | EI21: ='ФинРез Кампус'!K90 -> 0 | EJ21: ='ФинРез Кампус'!L90 -> 0 | EK21: ='ФинРез Кампус'!M90 -> 0 | ... EX21: ='ФинРез Кампус'!Z90 -> 0 | EY21: =SUM(EH21:EX21) -> 0
C22: 11 | D22: Инвестиционные расходы (включая приобретение основных средств) | E22: тыс. руб. | F22: ='[10]Данные для переноса'!F20 -> 124641.6 | G22: ='[10]Данные для переноса'!G20 -> 143386.88 | H22: ='[10]Данные для переноса'!H20 -> 63284.984 | I22: ='[10]Данные для переноса'!I20 -> 66132.809 | J22: ='[10]Данные для переноса'!J20 -> 68778.121 | K22: ='[10]Данные для переноса'!K20 -> 71529.246 | L22: ='[10]Данные для переноса'!L20 -> 74390.416 | M22: ='[10]Данные для переноса'!M20 -> 77366.032 | ... Z22: ='[10]Данные для переноса'!Z20 -> 128820.13 | AA22: 124641.6 | AB22: 143386.88 | AC22: 63284.984 | AD22: 66132.809 | AE22: 68778.121 | AF22: 71529.246 | AG22: 74390.416 | AH22: 77366.032 | AI22: 80460.674 | AJ22: 83679.101 | AK22: 87026.265 | AL22: 90507.315 | AM22: 94127.608 | AN22: 97892.712 | AO22: 101808.42 | AP22: 105880.76 | AQ22: 110115.99 | AR22: 114520.63 | AS22: 119101.45 | AT22: 123865.51 | AU22: 128820.13 | AV22: =AA22=F22 -> TRUE | AW22: =AB22=G22 -> TRUE | AX22: =AC22=H22 -> TRUE | AY22: =AD22=I22 -> TRUE | AZ22: =AE22=J22 -> TRUE | BA22: =AF22=K22 -> TRUE | BB22: =AG22=L22 -> TRUE | BC22: =AH22=M22 -> TRUE | ... BP22: =AU22=Z22 -> TRUE | BQ22: =SUM(J22:Z22) -> 1629870.4 | BR22: ='[10]Данные для переноса'!AB20 -> 124641.6 | BS22: ='[10]Данные для переноса'!AC20 -> 143386.88 | BT22: ='[10]Данные для переноса'!AD20 -> 63284.984 | BU22: ='[10]Данные для переноса'!AE20 -> 66132.809 | BV22: ='[10]Данные для переноса'!AF20 -> 68778.121 | BW22: ='[10]Данные для переноса'!AG20 -> 71529.246 | BX22: ='[10]Данные для переноса'!AH20 -> 74390.416 | BY22: ='[10]Данные для переноса'!AI20 -> 77366.032 | ... CL22: ='[10]Данные для переноса'!AV20 -> 128820.13 | CM22: 124641.6 | CN22: 143386.88 | CO22: 63284.984 | CP22: 66132.809 | CQ22: 68778.121 | CR22: 71529.246 | CS22: 74390.416 | CT22: 77366.032 | CU22: 80460.674 | CV22: 83679.101 | CW22: 87026.265 | CX22: 90507.315 | CY22: 94127.608 | CZ22: 97892.712 | DA22: 101808.42 | DB22: 105880.76 | DC22: 110115.99 | DD22: 114520.63 | DE22: 119101.45 | DF22: 123865.51 | DG22: 128820.13 | DH22: =CM22=BR22 -> TRUE | DI22: =CN22=BS22 -> TRUE | DJ22: =CO22=BT22 -> TRUE | DK22: =CP22=BU22 -> TRUE | DL22: =CQ22=BV22 -> TRUE | DM22: =CR22=BW22 -> TRUE | DN22: =CS22=BX22 -> TRUE | DO22: =CT22=BY22 -> TRUE | ... EB22: =DG22=CL22 -> TRUE | EC22: =SUM(BV22:CL22) -> 1629870.4 | ED22: =BR22-F22 -> 0 | EE22: =BS22-G22 -> 0 | EF22: =BT22-H22 -> 0 | EG22: =BU22-I22 -> 0 | EH22: =BV22-J22 -> 0 | EI22: =BW22-K22 -> 0 | EJ22: =BX22-L22 -> 0 | EK22: =BY22-M22 -> 0 | ... EX22: =CL22-Z22 -> 0 | EY22: =SUM(EH22:EX22) -> 0
C23: 12 | D23: Потребность в дофинансировании (базовая) | E23: тыс.руб. | F23: =F24+F28 -> 0 | G23: =G24+G28 -> 0 | H23: =H24+H28 -> 0 | I23: =I24+I28 -> 0 | J23: =J24+J28 -> 0 | K23: =K24+K28 -> 0 | L23: =L24+L28 -> 0 | M23: =M24+M28 -> 0 | ... Z23: =Z24+Z28 -> 0 | AA23: 0 | AB23: 0 | AC23: 0 | AD23: 0 | AE23: 0 | AF23: 0 | AG23: 0 | AH23: 0 | AI23: 0 | AJ23: 0 | AK23: 0 | AL23: 0 | AM23: 0 | AN23: 0 | AO23: 0 | AP23: 0 | AQ23: 0 | AR23: 0 | AS23: 0 | AT23: 0 | AU23: 0 | AV23: =AA23=F23 -> TRUE | AW23: =AB23=G23 -> TRUE | AX23: =AC23=H23 -> TRUE | AY23: =AD23=I23 -> TRUE | AZ23: =AE23=J23 -> TRUE | BA23: =AF23=K23 -> TRUE | BB23: =AG23=L23 -> TRUE | BC23: =AH23=M23 -> TRUE | ... BP23: =AU23=Z23 -> TRUE | BQ23: =SUM(J23:Z23) -> 0 | BR23: =BR24+BR28 -> 0 | BS23: =BS24+BS28 -> 0 | BT23: =BT24+BT28 -> 0 | BU23: =BU24+BU28 -> 0 | BV23: =BV24+BV28 -> 0 | BW23: =BW24+BW28 -> 0 | BX23: =BX24+BX28 -> 0 | BY23: =BY24+BY28 -> 124377.91 | ... CL23: =CL24+CL28 -> 980888.58 | CM23: 0 | CN23: 0 | CO23: 0 | CP23: 0 | CQ23: 0 | CR23: 0 | CS23: 0 | CT23: 124377.91 | CU23: 124377.91 | CV23: 0 | CW23: 0 | CX23: 0.0001639314 | CY23: 0.00016393047 | CZ23: 541439.27 | DA23: 1109137.6 | DB23: 989732.15 | DC23: 988200.82 | DD23: 694786.35 | DE23: 984797.45 | DF23: 982910.28 | DG23: 980888.58 | DH23: =CM23=BR23 -> TRUE | DI23: =CN23=BS23 -> TRUE | DJ23: =CO23=BT23 -> TRUE | DK23: =CP23=BU23 -> TRUE | DL23: =CQ23=BV23 -> TRUE | DM23: =CR23=BW23 -> TRUE | DN23: =CS23=BX23 -> TRUE | DO23: =CT23=BY23 -> TRUE | ... EB23: =DG23=CL23 -> TRUE | EC23: =SUM(BV23:CL23) -> 7271892.5 | ED23: =BR23 -> 0 | EE23: =BS23 -> 0 | EF23: =BT23 -> 0 | EG23: =BU23 -> 0 | EH23: =BV23 -> 0 | EI23: =BW23 -> 0 | EJ23: =BX23 -> 0 | EK23: =BY23 -> 124377.91 | ... EX23: =CL23 -> 980888.58 | EY23: =SUM(EH23:EX23) -> 7271892.5
C24: 13 | D24: Потребность в дофинансировании на ввод в эксплуатацию и оснащение (фин.результат) | E24: тыс. руб. | F24: ='[10]Данные для переноса'!F22 -> 0 | G24: ='[10]Данные для переноса'!G22 -> 0 | H24: ='[10]Данные для переноса'!H22 -> 0 | I24: ='[10]Данные для переноса'!I22 -> 0 | J24: ='[10]Данные для переноса'!J22 -> 0 | K24: ='[10]Данные для переноса'!K22 -> 0 | L24: ='[10]Данные для переноса'!L22 -> 0 | M24: ='[10]Данные для переноса'!M22 -> 0 | ... Z24: ='[10]Данные для переноса'!Z22 -> 0 | AV24: =AA24=F24 -> TRUE | AW24: =AB24=G24 -> TRUE | AX24: =AC24=H24 -> TRUE | AY24: =AD24=I24 -> TRUE | AZ24: =AE24=J24 -> TRUE | BA24: =AF24=K24 -> TRUE | BB24: =AG24=L24 -> TRUE | BC24: =AH24=M24 -> TRUE | ... BP24: =AU24=Z24 -> TRUE | BQ24: =SUM(J24:Z24) -> 0 | BR24: ='[10]Данные для переноса'!AB22 -> 0 | BS24: ='[10]Данные для переноса'!AC22 -> 0 | BT24: ='[10]Данные для переноса'!AD22 -> 0 | BU24: ='[10]Данные для переноса'!AE22 -> 0 | BV24: ='[10]Данные для переноса'!AF22 -> 0 | BW24: ='[10]Данные для переноса'!AG22 -> 0 | BX24: ='[10]Данные для переноса'!AH22 -> 0 | BY24: ='[10]Данные для переноса'!AI22 -> 124377.91 | ... CL24: ='[10]Данные для переноса'!AV22 -> 0 | CM24: 0 | CN24: 0 | CO24: 0 | CP24: 0 | CQ24: 0 | CR24: 0 | CS24: 0 | CT24: 124377.91 | CU24: 0 | CV24: 0 | CW24: 0 | CX24: 0.0001639314 | CY24: 0 | CZ24: 124377.91 | DA24: 0 | DB24: 0 | DC24: 0 | DD24: 0 | DE24: 0 | DF24: 0 | DG24: 0 | DH24: =CM24=BR24 -> TRUE | DI24: =CN24=BS24 -> TRUE | DJ24: =CO24=BT24 -> TRUE | DK24: =CP24=BU24 -> TRUE | DL24: =CQ24=BV24 -> TRUE | DM24: =CR24=BW24 -> TRUE | DN24: =CS24=BX24 -> TRUE | DO24: =CT24=BY24 -> TRUE | ... EB24: =DG24=CL24 -> TRUE | EC24: =SUM(BV24:CL24) -> 248755.81 | ED24: =BR24 -> 0 | EE24: =BS24 -> 0 | EF24: =BT24 -> 0 | EG24: =BU24 -> 0 | EH24: =BV24 -> 0 | EI24: =BW24 -> 0 | EJ24: =BX24 -> 0 | EK24: =BY24 -> 124377.91 | ... EX24: =CL24 -> 0 | EY24: =SUM(EH24:EX24) -> 248755.81
D25: за счет федерального бюджета | E25: тыс. руб. | F25: ='[10]Данные для переноса'!F23 -> 0 | G25: ='[10]Данные для переноса'!G23 -> 0 | H25: ='[10]Данные для переноса'!H23 -> 0 | I25: ='[10]Данные для переноса'!I23 -> 0 | J25: ='[10]Данные для переноса'!J23 -> 0 | K25: ='[10]Данные для переноса'!K23 -> 0 | L25: ='[10]Данные для переноса'!L23 -> 0 | M25: ='[10]Данные для переноса'!M23 -> 0 | ... Z25: ='[10]Данные для переноса'!Z23 -> 0 | AV25: =AA25=F25 -> TRUE | AW25: =AB25=G25 -> TRUE | AX25: =AC25=H25 -> TRUE | AY25: =AD25=I25 -> TRUE | AZ25: =AE25=J25 -> TRUE | BA25: =AF25=K25 -> TRUE | BB25: =AG25=L25 -> TRUE | BC25: =AH25=M25 -> TRUE | ... BP25: =AU25=Z25 -> TRUE | BQ25: =SUM(J25:Z25) -> 0 | BR25: ='[10]Данные для переноса'!AB23 -> 0 | BS25: ='[10]Данные для переноса'!AC23 -> 0 | BT25: ='[10]Данные для переноса'!AD23 -> 0 | BU25: ='[10]Данные для переноса'!AE23 -> 0 | BV25: ='[10]Данные для переноса'!AF23 -> 0 | BW25: ='[10]Данные для переноса'!AG23 -> 0 | BX25: ='[10]Данные для переноса'!AH23 -> 0 | BY25: ='[10]Данные для переноса'!AI23 -> 0 | ... CL25: ='[10]Данные для переноса'!AV23 -> 0 | CM25: 0 | CN25: 0 | CO25: 0 | CP25: 0 | CQ25: 0 | CR25: 0 | CS25: 0 | CT25: 0 | CU25: 6651958.7 | CV25: 6918037 | CW25: 4796505.7 | CX25: 4988365.9 | CY25: 0 | CZ25: 0 | DA25: 0 | DB25: 0 | DC25: 0 | DD25: 0 | DE25: 0 | DF25: 0 | DG25: 0 | DH25: =CM25=BR25 -> TRUE | DI25: =CN25=BS25 -> TRUE | DJ25: =CO25=BT25 -> TRUE | DK25: =CP25=BU25 -> TRUE | DL25: =CQ25=BV25 -> TRUE | DM25: =CR25=BW25 -> TRUE | DN25: =CS25=BX25 -> TRUE | DO25: =CT25=BY25 -> TRUE | ... EB25: =DG25=CL25 -> TRUE | EC25: =SUM(BV25:CL25) -> 23354867 | ED25: =BR25 -> 0 | EE25: =BS25 -> 0 | EF25: =BT25 -> 0 | EG25: =BU25 -> 0 | EH25: =BV25 -> 0 | EI25: =BW25 -> 0 | EJ25: =BX25 -> 0 | EK25: =BY25 -> 0 | ... EX25: =CL25 -> 0 | EY25: =SUM(EH25:EX25) -> 23354867
D26: за счет регионального и местного бюджета | E26: тыс. руб. | F26: ='[10]Данные для переноса'!F24 -> 0 | G26: ='[10]Данные для переноса'!G24 -> 0 | H26: ='[10]Данные для переноса'!H24 -> 0 | I26: ='[10]Данные для переноса'!I24 -> 0 | J26: ='[10]Данные для переноса'!J24 -> 0 | K26: ='[10]Данные для переноса'!K24 -> 0 | L26: ='[10]Данные для переноса'!L24 -> 0 | M26: ='[10]Данные для переноса'!M24 -> 0 | ... Z26: ='[10]Данные для переноса'!Z24 -> 0 | AV26: =AA26=F26 -> TRUE | AW26: =AB26=G26 -> TRUE | AX26: =AC26=H26 -> TRUE | AY26: =AD26=I26 -> TRUE | AZ26: =AE26=J26 -> TRUE | BA26: =AF26=K26 -> TRUE | BB26: =AG26=L26 -> TRUE | BC26: =AH26=M26 -> TRUE | ... BP26: =AU26=Z26 -> TRUE | BQ26: =SUM(J26:Z26) -> 0 | BR26: ='[10]Данные для переноса'!AB24 -> 0 | BS26: ='[10]Данные для переноса'!AC24 -> 0 | BT26: ='[10]Данные для переноса'!AD24 -> 0 | BU26: ='[10]Данные для переноса'!AE24 -> 0 | BV26: ='[10]Данные для переноса'!AF24 -> 0 | BW26: ='[10]Данные для переноса'!AG24 -> 0 | BX26: ='[10]Данные для переноса'!AH24 -> 0 | BY26: ='[10]Данные для переноса'!AI24 -> 0 | ... CL26: ='[10]Данные для переноса'!AV24 -> 0 | CM26: 0 | CN26: 0 | CO26: 0 | CP26: 0 | CQ26: 0 | CR26: 0 | CS26: 0 | CT26: 0 | CU26: 0 | CV26: 0 | CW26: 0 | CX26: 0 | CY26: 1100000 | CZ26: 0 | DA26: 0 | DB26: 0 | DC26: 0 | DD26: 0 | DE26: 0 | DF26: 0 | DG26: 0 | DH26: =CM26=BR26 -> TRUE | DI26: =CN26=BS26 -> TRUE | DJ26: =CO26=BT26 -> TRUE | DK26: =CP26=BU26 -> TRUE | DL26: =CQ26=BV26 -> TRUE | DM26: =CR26=BW26 -> TRUE | DN26: =CS26=BX26 -> TRUE | DO26: =CT26=BY26 -> TRUE | ... EB26: =DG26=CL26 -> TRUE | EC26: =SUM(BV26:CL26) -> 1100000 | ED26: =BR26 -> 0 | EE26: =BS26 -> 0 | EF26: =BT26 -> 0 | EG26: =BU26 -> 0 | EH26: =BV26 -> 0 | EI26: =BW26 -> 0 | EJ26: =BX26 -> 0 | EK26: =BY26 -> 0 | ... EX26: =CL26 -> 0 | EY26: =SUM(EH26:EX26) -> 1100000
D27: за счет средств приносящей доход деятельности | E27: тыс. руб. | F27: ='[10]Данные для переноса'!F25 -> 0 | G27: ='[10]Данные для переноса'!G25 -> 0 | H27: ='[10]Данные для переноса'!H25 -> 0 | I27: ='[10]Данные для переноса'!I25 -> 0 | J27: ='[10]Данные для переноса'!J25 -> 0 | K27: ='[10]Данные для переноса'!K25 -> 0 | L27: ='[10]Данные для переноса'!L25 -> 0 | M27: ='[10]Данные для переноса'!M25 -> 0 | ... Z27: ='[10]Данные для переноса'!Z25 -> 0 | AV27: =AA27=F27 -> TRUE | AW27: =AB27=G27 -> TRUE | AX27: =AC27=H27 -> TRUE | AY27: =AD27=I27 -> TRUE | AZ27: =AE27=J27 -> TRUE | BA27: =AF27=K27 -> TRUE | BB27: =AG27=L27 -> TRUE | BC27: =AH27=M27 -> TRUE | ... BP27: =AU27=Z27 -> TRUE | BQ27: =SUM(J27:Z27) -> 0 | BR27: ='[10]Данные для переноса'!AB25 -> 0 | BS27: ='[10]Данные для переноса'!AC25 -> 0 | BT27: ='[10]Данные для переноса'!AD25 -> 0 | BU27: ='[10]Данные для переноса'!AE25 -> 0 | BV27: ='[10]Данные для переноса'!AF25 -> 0 | BW27: ='[10]Данные для переноса'!AG25 -> 1146128.1 | BX27: ='[10]Данные для переноса'!AH25 -> 598568.68 | BY27: ='[10]Данные для переноса'!AI25 -> 248880.19 | ... CL27: ='[10]Данные для переноса'!AV25 -> 0 | CM27: 0 | CN27: 0 | CO27: 0 | CP27: 0 | CQ27: 0 | CR27: 1146128.1 | CS27: 598568.68 | CT27: 248880.19 | CU27: 134307.14 | CV27: 139679.42 | CW27: 1081434.6 | CX27: 1413505.1 | CY27: 1449678.3 | CZ27: 0 | DA27: 0 | DB27: 0 | DC27: 0 | DD27: 0 | DE27: 0 | DF27: 0 | DG27: 0 | DH27: =CM27=BR27 -> TRUE | DI27: =CN27=BS27 -> TRUE | DJ27: =CO27=BT27 -> TRUE | DK27: =CP27=BU27 -> TRUE | DL27: =CQ27=BV27 -> TRUE | DM27: =CR27=BW27 -> TRUE | DN27: =CS27=BX27 -> TRUE | DO27: =CT27=BY27 -> TRUE | ... EB27: =DG27=CL27 -> TRUE | EC27: =SUM(BV27:CL27) -> 6212181.4 | ED27: =BR27 -> 0 | EE27: =BS27 -> 0 | EF27: =BT27 -> 0 | EG27: =BU27 -> 0 | EH27: =BV27 -> 0 | EI27: =BW27 -> 1146128.1 | EJ27: =BX27 -> 598568.68 | EK27: =BY27 -> 248880.19 | ... EX27: =CL27 -> 0 | EY27: =SUM(EH27:EX27) -> 6212181.4
C28: 14 | D28: Потребность в дофинансировании содержания имущества и операционной деятельности (фин.результат) | E28: тыс. руб. | F28: ='[10]Данные для переноса'!F26 -> 0 | G28: ='[10]Данные для переноса'!G26 -> 0 | H28: ='[10]Данные для переноса'!H26 -> 0 | I28: ='[10]Данные для переноса'!I26 -> 0 | J28: ='[10]Данные для переноса'!J26 -> 0 | K28: ='[10]Данные для переноса'!K26 -> 0 | L28: ='[10]Данные для переноса'!L26 -> 0 | M28: ='[10]Данные для переноса'!M26 -> 0 | ... Z28: ='[10]Данные для переноса'!Z26 -> 0 | AV28: =AA28=F28 -> TRUE | AW28: =AB28=G28 -> TRUE | AX28: =AC28=H28 -> TRUE | AY28: =AD28=I28 -> TRUE | AZ28: =AE28=J28 -> TRUE | BA28: =AF28=K28 -> TRUE | BB28: =AG28=L28 -> TRUE | BC28: =AH28=M28 -> TRUE | ... BP28: =AU28=Z28 -> TRUE | BQ28: =SUM(J28:Z28) -> 0 | BR28: ='[10]Данные для переноса'!AB26 -> 0 | BS28: ='[10]Данные для переноса'!AC26 -> 0 | BT28: ='[10]Данные для переноса'!AD26 -> 0 | BU28: ='[10]Данные для переноса'!AE26 -> 0 | BV28: ='[10]Данные для переноса'!AF26 -> 0 | BW28: ='[10]Данные для переноса'!AG26 -> 0 | BX28: ='[10]Данные для переноса'!AH26 -> 0 | BY28: ='[10]Данные для переноса'!AI26 -> 0 | ... CL28: ='[10]Данные для переноса'!AV26 -> 980888.58 | CM28: 0 | CN28: 0 | CO28: 0 | CP28: 0 | CQ28: 0 | CR28: 0 | CS28: 0 | CT28: 0 | CU28: 0 | CV28: 0 | CW28: 0 | CX28: 0 | CY28: 0 | CZ28: 417061.36 | DA28: 984759.66 | DB28: 989732.15 | DC28: 988200.82 | DD28: 694786.35 | DE28: 984797.45 | DF28: 982910.28 | DG28: 980888.58 | DH28: =CM28=BR28 -> TRUE | DI28: =CN28=BS28 -> TRUE | DJ28: =CO28=BT28 -> TRUE | DK28: =CP28=BU28 -> TRUE | DL28: =CQ28=BV28 -> TRUE | DM28: =CR28=BW28 -> TRUE | DN28: =CS28=BX28 -> TRUE | DO28: =CT28=BY28 -> TRUE | ... EB28: =DG28=CL28 -> TRUE | EC28: =SUM(BV28:CL28) -> 7023136.7 | ED28: =BR28 -> 0 | EE28: =BS28 -> 0 | EF28: =BT28 -> 0 | EG28: =BU28 -> 0 | EH28: =BV28 -> 0 | EI28: =BW28 -> 0 | EJ28: =BX28 -> 0 | EK28: =BY28 -> 0 | ... EX28: =CL28 -> 980888.58 | EY28: =SUM(EH28:EX28) -> 7023136.7
D29: за счет федерального бюджета | E29: тыс. руб. | F29: ='[10]Данные для переноса'!F27 -> 0 | G29: ='[10]Данные для переноса'!G27 -> 0 | H29: ='[10]Данные для переноса'!H27 -> 0 | I29: ='[10]Данные для переноса'!I27 -> 0 | J29: ='[10]Данные для переноса'!J27 -> 0 | K29: ='[10]Данные для переноса'!K27 -> 0 | L29: ='[10]Данные для переноса'!L27 -> 0 | M29: ='[10]Данные для переноса'!M27 -> 0 | ... Z29: ='[10]Данные для переноса'!Z27 -> 0 | AV29: =AA29=F29 -> TRUE | AW29: =AB29=G29 -> TRUE | AX29: =AC29=H29 -> TRUE | AY29: =AD29=I29 -> TRUE | AZ29: =AE29=J29 -> TRUE | BA29: =AF29=K29 -> TRUE | BB29: =AG29=L29 -> TRUE | BC29: =AH29=M29 -> TRUE | ... BP29: =AU29=Z29 -> TRUE | BQ29: =SUM(J29:Z29) -> 0 | BR29: ='[10]Данные для переноса'!AB27 -> 0 | BS29: ='[10]Данные для переноса'!AC27 -> 0 | BT29: ='[10]Данные для переноса'!AD27 -> 0 | BU29: ='[10]Данные для переноса'!AE27 -> 0 | BV29: ='[10]Данные для переноса'!AF27 -> 0 | BW29: ='[10]Данные для переноса'!AG27 -> 0 | BX29: ='[10]Данные для переноса'!AH27 -> 0 | BY29: ='[10]Данные для переноса'!AI27 -> 0 | ... CL29: ='[10]Данные для переноса'!AV27 -> 0 | CM29: 0 | CN29: 0 | CO29: 0 | CP29: 0 | CQ29: 0 | CR29: 0 | CS29: 0 | CT29: 0 | CU29: 0 | CV29: 0 | CW29: 0 | CX29: 0 | CY29: 0 | CZ29: 0 | DA29: 0 | DB29: 0 | DC29: 0 | DD29: 0 | DE29: 0 | DF29: 0 | DG29: 0 | DH29: =CM29=BR29 -> TRUE | DI29: =CN29=BS29 -> TRUE | DJ29: =CO29=BT29 -> TRUE | DK29: =CP29=BU29 -> TRUE | DL29: =CQ29=BV29 -> TRUE | DM29: =CR29=BW29 -> TRUE | DN29: =CS29=BX29 -> TRUE | DO29: =CT29=BY29 -> TRUE | ... EB29: =DG29=CL29 -> TRUE | EC29: =SUM(BV29:CL29) -> 0 | ED29: =BR29 -> 0 | EE29: =BS29 -> 0 | EF29: =BT29 -> 0 | EG29: =BU29 -> 0 | EH29: =BV29 -> 0 | EI29: =BW29 -> 0 | EJ29: =BX29 -> 0 | EK29: =BY29 -> 0 | ... EX29: =CL29 -> 0 | EY29: =SUM(EH29:EX29) -> 0
D30: за счет регионального и местного бюджета | E30: тыс. руб. | F30: ='[10]Данные для переноса'!F28 -> 0 | G30: ='[10]Данные для переноса'!G28 -> 0 | H30: ='[10]Данные для переноса'!H28 -> 0 | I30: ='[10]Данные для переноса'!I28 -> 0 | J30: ='[10]Данные для переноса'!J28 -> 0 | K30: ='[10]Данные для переноса'!K28 -> 0 | L30: ='[10]Данные для переноса'!L28 -> 0 | M30: ='[10]Данные для переноса'!M28 -> 0 | ... Z30: ='[10]Данные для переноса'!Z28 -> 0 | AV30: =AA30=F30 -> TRUE | AW30: =AB30=G30 -> TRUE | AX30: =AC30=H30 -> TRUE | AY30: =AD30=I30 -> TRUE | AZ30: =AE30=J30 -> TRUE | BA30: =AF30=K30 -> TRUE | BB30: =AG30=L30 -> TRUE | BC30: =AH30=M30 -> TRUE | ... BP30: =AU30=Z30 -> TRUE | BQ30: =SUM(J30:Z30) -> 0 | BR30: ='[10]Данные для переноса'!AB28 -> 0 | BS30: ='[10]Данные для переноса'!AC28 -> 0 | BT30: ='[10]Данные для переноса'!AD28 -> 0 | BU30: ='[10]Данные для переноса'!AE28 -> 0 | BV30: ='[10]Данные для переноса'!AF28 -> 0 | BW30: ='[10]Данные для переноса'!AG28 -> 0 | BX30: ='[10]Данные для переноса'!AH28 -> 0 | BY30: ='[10]Данные для переноса'!AI28 -> 0 | ... CL30: ='[10]Данные для переноса'!AV28 -> 0 | CM30: 0 | CN30: 0 | CO30: 0 | CP30: 0 | CQ30: 0 | CR30: 0 | CS30: 0 | CT30: 0 | CU30: 0 | CV30: 0 | CW30: 0 | CX30: 0 | CY30: 0 | CZ30: 0 | DA30: 0 | DB30: 0 | DC30: 0 | DD30: 0 | DE30: 0 | DF30: 0 | DG30: 0 | DH30: =CM30=BR30 -> TRUE | DI30: =CN30=BS30 -> TRUE | DJ30: =CO30=BT30 -> TRUE | DK30: =CP30=BU30 -> TRUE | DL30: =CQ30=BV30 -> TRUE | DM30: =CR30=BW30 -> TRUE | DN30: =CS30=BX30 -> TRUE | DO30: =CT30=BY30 -> TRUE | ... EB30: =DG30=CL30 -> TRUE | EC30: =SUM(BV30:CL30) -> 0 | ED30: =BR30 -> 0 | EE30: =BS30 -> 0 | EF30: =BT30 -> 0 | EG30: =BU30 -> 0 | EH30: =BV30 -> 0 | EI30: =BW30 -> 0 | EJ30: =BX30 -> 0 | EK30: =BY30 -> 0 | ... EX30: =CL30 -> 0 | EY30: =SUM(EH30:EX30) -> 0
D31: за счет средств приносящей доход деятельности | E31: тыс. руб. | F31: ='[10]Данные для переноса'!F29 -> 0 | G31: ='[10]Данные для переноса'!G29 -> 0 | H31: ='[10]Данные для переноса'!H29 -> 0 | I31: ='[10]Данные для переноса'!I29 -> 0 | J31: ='[10]Данные для переноса'!J29 -> 0 | K31: ='[10]Данные для переноса'!K29 -> 0 | L31: ='[10]Данные для переноса'!L29 -> 0 | M31: ='[10]Данные для переноса'!M29 -> 0 | ... Z31: ='[10]Данные для переноса'!Z29 -> 0 | AV31: =AA31=F31 -> TRUE | AW31: =AB31=G31 -> TRUE | AX31: =AC31=H31 -> TRUE | AY31: =AD31=I31 -> TRUE | AZ31: =AE31=J31 -> TRUE | BA31: =AF31=K31 -> TRUE | BB31: =AG31=L31 -> TRUE | BC31: =AH31=M31 -> TRUE | ... BP31: =AU31=Z31 -> TRUE | BQ31: =SUM(J31:Z31) -> 0 | BR31: ='[10]Данные для переноса'!AB29 -> 0 | BS31: ='[10]Данные для переноса'!AC29 -> 0 | BT31: ='[10]Данные для переноса'!AD29 -> 0 | BU31: ='[10]Данные для переноса'!AE29 -> 0 | BV31: ='[10]Данные для переноса'!AF29 -> 0 | BW31: ='[10]Данные для переноса'!AG29 -> 0 | BX31: ='[10]Данные для переноса'!AH29 -> 0 | BY31: ='[10]Данные для переноса'!AI29 -> 0 | ... CL31: ='[10]Данные для переноса'!AV29 -> 980888.58 | CM31: 0 | CN31: 0 | CO31: 0 | CP31: 0 | CQ31: 0 | CR31: 0 | CS31: 0 | CT31: 0 | CU31: 0 | CV31: 0 | CW31: 0 | CX31: 0 | CY31: 0 | CZ31: 417061.36 | DA31: 984759.66 | DB31: 989732.15 | DC31: 988200.82 | DD31: 694786.35 | DE31: 984797.45 | DF31: 982910.28 | DG31: 980888.58 | DH31: =CM31=BR31 -> TRUE | DI31: =CN31=BS31 -> TRUE | DJ31: =CO31=BT31 -> TRUE | DK31: =CP31=BU31 -> TRUE | DL31: =CQ31=BV31 -> TRUE | DM31: =CR31=BW31 -> TRUE | DN31: =CS31=BX31 -> TRUE | DO31: =CT31=BY31 -> TRUE | ... EB31: =DG31=CL31 -> TRUE | EC31: =SUM(BV31:CL31) -> 7023136.7 | ED31: =BR31 -> 0 | EE31: =BS31 -> 0 | EF31: =BT31 -> 0 | EG31: =BU31 -> 0 | EH31: =BV31 -> 0 | EI31: =BW31 -> 0 | EJ31: =BX31 -> 0 | EK31: =BY31 -> 0 | ... EX31: =CL31 -> 980888.58 | EY31: =SUM(EH31:EX31) -> 7023136.7
C32: 15 | D32: Положительный денежный поток от деятельности университета | E32: тыс. руб. | F32: ='[10]Данные для переноса'!F30 -> 0 | G32: ='[10]Данные для переноса'!G30 -> 0 | H32: ='[10]Данные для переноса'!H30 -> 0 | I32: ='[10]Данные для переноса'!I30 -> 0 | J32: ='[10]Данные для переноса'!J30 -> 0 | K32: ='[10]Данные для переноса'!K30 -> 0 | L32: ='[10]Данные для переноса'!L30 -> 0 | M32: ='[10]Данные для переноса'!M30 -> 0 | ... Z32: ='[10]Данные для переноса'!Z30 -> 0 | AV32: =AA32=F32 -> TRUE | AW32: =AB32=G32 -> TRUE | AX32: =AC32=H32 -> TRUE | AY32: =AD32=I32 -> TRUE | AZ32: =AE32=J32 -> TRUE | BA32: =AF32=K32 -> TRUE | BB32: =AG32=L32 -> TRUE | BC32: =AH32=M32 -> TRUE | ... BP32: =AU32=Z32 -> TRUE | BQ32: =SUM(J32:Z32) -> 0 | BR32: ='[10]Данные для переноса'!AB30 -> 0 | BS32: ='[10]Данные для переноса'!AC30 -> 0 | BT32: ='[10]Данные для переноса'!AD30 -> 0 | BU32: ='[10]Данные для переноса'!AE30 -> 0 | BV32: ='[10]Данные для переноса'!AF30 -> 0 | BW32: ='[10]Данные для переноса'!AG30 -> 0 | BX32: ='[10]Данные для переноса'!AH30 -> 0 | BY32: ='[10]Данные для переноса'!AI30 -> 0 | ... CL32: ='[10]Данные для переноса'!AV30 -> 0 | CM32: 0 | CN32: 0 | CO32: 0 | CP32: 0 | CQ32: 0 | CR32: 0 | CS32: 0 | CT32: 0 | CU32: 124377.91 | CV32: 0 | CW32: 0 | CX32: 0 | CY32: 0.00016393047 | CZ32: 0 | DA32: 124377.91 | DB32: 0 | DC32: 0 | DD32: 0 | DE32: 0 | DF32: 0 | DG32: 0 | DH32: =CM32=BR32 -> TRUE | DI32: =CN32=BS32 -> TRUE | DJ32: =CO32=BT32 -> TRUE | DK32: =CP32=BU32 -> TRUE | DL32: =CQ32=BV32 -> TRUE | DM32: =CR32=BW32 -> TRUE | DN32: =CS32=BX32 -> TRUE | DO32: =CT32=BY32 -> TRUE | ... EB32: =DG32=CL32 -> TRUE | EC32: =SUM(BV32:CL32) -> 248755.81 | ED32: =BR32 -> 0 | EE32: =BS32 -> 0 | EF32: =BT32 -> 0 | EG32: =BU32 -> 0 | EH32: =BV32 -> 0 | EI32: =BW32 -> 0 | EJ32: =BX32 -> 0 | EK32: =BY32 -> 0 | ... EX32: =CL32 -> 0 | EY32: =SUM(EH32:EX32) -> 248755.81
C33: 16 | D33: Доходы (по источникам финансирования) | E33: тыс.руб. | F33: =SUM(F34:F36) -> 10491307 | G33: =SUM(G34:G36) -> 12413481 | H33: =SUM(H34:H36) -> 15281575 | I33: =SUM(I34:I36) -> 16541920 | J33: =SUM(J34:J36) -> 17535322 | K33: =SUM(K34:K36) -> 18604050 | L33: =SUM(L34:L36) -> 19471726 | M33: =SUM(M34:M36) -> 20345931 | ... Z33: =SUM(Z34:Z36) -> 37046659 | AA33: 10491307 | AB33: 12413481 | AC33: 15281575 | AD33: 16541920 | AE33: 17535322 | AF33: 18604050 | AG33: 19471726 | AH33: 20345931 | AI33: 21286763 | AJ33: 22270585 | AK33: 23306537 | AL33: 24394115 | AM33: 25534540 | AN33: 26737601 | AO33: 27996442 | AP33: 29322370 | AQ33: 30714438 | AR33: 32179106 | AS33: 33721727 | AT33: 35342301 | AU33: 37046659 | AV33: =AA33=F33 -> TRUE | AW33: =AB33=G33 -> TRUE | AX33: =AC33=H33 -> TRUE | AY33: =AD33=I33 -> TRUE | AZ33: =AE33=J33 -> TRUE | BA33: =AF33=K33 -> TRUE | BB33: =AG33=L33 -> TRUE | BC33: =AH33=M33 -> TRUE | ... BP33: =AU33=Z33 -> TRUE | BQ33: =SUM(BQ34:BQ36) -> 4.4581021e+08 | BR33: =SUM(BR34:BR36) -> 10491307 | BS33: =SUM(BS34:BS36) -> 12413481 | BT33: =SUM(BT34:BT36) -> 15281575 | BU33: =SUM(BU34:BU36) -> 16798888 | BV33: =SUM(BV34:BV36) -> 18753447 | BW33: =SUM(BW34:BW36) -> 21410712 | BX33: =SUM(BX34:BX36) -> 22186167 | ... CL33: =SUM(CL34:CL36) -> 45147510 | CM33: 10491307 | CN33: 12413481 | CO33: 15281575 | CP33: 16798888 | CQ33: 18753447 | CR33: 22555695 | CS33: 22784137 | CT33: 23185804 | CU33: 30617896 | CV33: 31951038 | CW33: 32825788 | CX33: 34847175 | CY33: 32263298 | CZ33: 34612033 | DA33: 34995670 | DB33: 36520678 | DC33: 38080610 | DD33: 39003424 | DE33: 41442268 | DF33: 43244257 | DG33: 45147510 | DH33: =CM33=BR33 -> TRUE | DI33: =CN33=BS33 -> TRUE | DJ33: =CO33=BT33 -> TRUE | DK33: =CP33=BU33 -> TRUE | DL33: =CQ33=BV33 -> TRUE | DM33: =CR33=BW33 -> FALSE | DN33: =CS33=BX33 -> FALSE | DO33: =CT33=BY33 -> FALSE | ... EB33: =DG33=CL33 -> TRUE | EC33: =SUM(EC34:EC36) -> 5.5493389e+08 | ED33: =BR33-F33 -> 0 | EE33: =BS33-G33 -> 0 | EF33: =BT33-H33 -> 0 | EG33: =BU33-I33 -> 256967.63 | EH33: =BV33-J33 -> 1218124.6 | EI33: =BW33-K33 -> 2806662.3 | EJ33: =BX33-L33 -> 2714441 | EK33: =BY33-M33 -> 2591117.7 | ... EX33: =CL33-Z33 -> 8100851.1 | EY33: =SUM(EY34:EY36) -> 1.0912368e+08
C34: 17 | D34: Приносящая доход деятельность | E34: тыс.руб. | F34: ='[10]Данные для переноса'!F32 -> 3675606.7 | G34: ='[10]Данные для переноса'!G32 -> 4727319.6 | H34: ='[10]Данные для переноса'!H32 -> 6075733.7 | I34: ='[10]Данные для переноса'!I32 -> 6827688.9 | J34: ='[10]Данные для переноса'!J32 -> 7324213.7 | K34: ='[10]Данные для переноса'!K32 -> 7844637 | L34: ='[10]Данные для переноса'!L32 -> 8182466.4 | M34: ='[10]Данные для переноса'!M32 -> 8506790.4 | ... Z34: ='[10]Данные для переноса'!Z32 -> 14164333 | AA34: 3675606.7 | AB34: 4727319.6 | AC34: 6075733.7 | AD34: 6827688.9 | AE34: 7324213.7 | AF34: 7844637 | AG34: 8182466.4 | AH34: 8506790.4 | AI34: 8847056 | AJ34: 9200931.1 | AK34: 9568963.1 | AL34: 9951716.2 | AM34: 10349779 | AN34: 10763764 | AO34: 11194308 | AP34: 11642075 | AQ34: 12107753 | AR34: 12592057 | AS34: 13095732 | AT34: 13619557 | AU34: 14164333 | AV34: =AA34=F34 -> TRUE | AW34: =AB34=G34 -> TRUE | AX34: =AC34=H34 -> TRUE | AY34: =AD34=I34 -> TRUE | AZ34: =AE34=J34 -> TRUE | BA34: =AF34=K34 -> TRUE | BB34: =AG34=L34 -> TRUE | BC34: =AH34=M34 -> TRUE | ... BP34: =AU34=Z34 -> TRUE | BQ34: =SUM(J34:Z34) -> 1.7895613e+08 | BR34: ='[10]Данные для переноса'!AB32 -> 3675606.7 | BS34: ='[10]Данные для переноса'!AC32 -> 4727319.6 | BT34: ='[10]Данные для переноса'!AD32 -> 6075733.7 | BU34: ='[10]Данные для переноса'!AE32 -> 7036844.8 | BV34: ='[10]Данные для переноса'!AF32 -> 8448156.1 | BW34: ='[10]Данные для переноса'!AG32 -> 10560531 | BX34: ='[10]Данные для переноса'!AH32 -> 10810959 | BY34: ='[10]Данные для переноса'!AI32 -> 11017337 | ... CL34: ='[10]Данные для переноса'!AV32 -> 22308078 | CM34: 3675606.7 | CN34: 4727319.6 | CO34: 6075733.7 | CP34: 7036844.8 | CQ34: 8448156.1 | CR34: 10560531 | CS34: 10810959 | CT34: 11017337 | CU34: 11324064 | CV34: 11762484 | CW34: 13154845 | CX34: 13955474 | CY34: 14485614 | CZ34: 16885895 | DA34: 18165670 | DB34: 18822461 | DC34: 19466635 | DD34: 19420449 | DE34: 20832479 | DF34: 21550646 | DG34: 22308078 | DH34: =CM34=BR34 -> TRUE | DI34: =CN34=BS34 -> TRUE | DJ34: =CO34=BT34 -> TRUE | DK34: =CP34=BU34 -> TRUE | DL34: =CQ34=BV34 -> TRUE | DM34: =CR34=BW34 -> TRUE | DN34: =CS34=BX34 -> TRUE | DO34: =CT34=BY34 -> TRUE | ... EB34: =DG34=CL34 -> TRUE | EC34: =SUM(BV34:CL34) -> 2.6297178e+08 | ED34: =BR34-F34 -> 0 | EE34: =BS34-G34 -> 0 | EF34: =BT34-H34 -> 0 | EG34: =BU34-I34 -> 209155.85 | EH34: =BV34-J34 -> 1123942.4 | EI34: =BW34-K34 -> 2715894.3 | EJ34: =BX34-L34 -> 2628492.8 | EK34: =BY34-M34 -> 2510547 | ... EX34: =CL34-Z34 -> 8143744.8 | EY34: =SUM(EH34:EX34) -> 84015646
